Workbook

Sheet Weekly Stats
A1: UNCVRD — WEEKLY STATS
A2: From ▸ | B2: 46199 | C2: To ▸ | D2: 46205 | E2: Creator ▸ | F2: All | H2: =TEXT($B$2,"mmm d")&" → "&TEXT($D$2,"mmm d")&" (pick any dates — set From=To for a single day)"
A3: Sheet ID ▸ | D3: Spend = Clicks × the CPC you type per platform (yellow cells in the CPC column). Paste sheet ID for day-by-day manual overrides.
A4: Metrics i need to know | B4: Clicks | C4: Fans | D4: Spend | E4: CAC | F4: CPC | G4: CVR | H4: Attributed Revenue | I4: Total LTV 48h | J4: Total LTV 7d | K4: Total LTV 14d | L4: Total LTV 30d | M4: ROAS | N4: Agency Profit
A5: Meta | B5: =SUMIFS(Data!$D:$D,Data!$A:$A,">="&$B$2,Data!$A:$A,"<="&$D$2,Data!$C:$C,"Meta",Data!$B:$B,IF($F$2="All","*",$F$2)) | C5: =SUMIFS(Data!$E:$E,Data!$A:$A,">="&$B$2,Data!$A:$A,"<="&$D$2,Data!$C:$C,"Meta",Data!$B:$B,IF($F$2="All","*",$F$2)) | D5: =B5*F5 | E5: =IFERROR(D5/C5,"") | F5: 0.75 | G5: =IFERROR(C5/B5,"") | H5: =SUMIFS(Data!$G:$G,Data!$A:$A,">="&$B$2,Data!$A:$A,"<="&$D$2,Data!$C:$C,"Meta",Data!$B:$B,IF($F$2="All","*",$F$2)) | I5: =IFERROR(SUMIFS(Cohort!$E:$E,Cohort!$B:$B,"Meta",Cohort!$A:$A,IF($F$2="All","*",$F$2))/SUMIFS(Cohort!$C:$C,Cohort!$B:$B,"Meta",Cohort!$A:$A,IF($F$2="All","*",$F$2)),"") | J5: =IFERROR(SUMIFS(Cohort!$F:$F,Cohort!$B:$B,"Meta",Cohort!$A:$A,IF($F$2="All","*",$F$2))/SUMIFS(Cohort!$C:$C,Cohort!$B:$B,"Meta",Cohort!$A:$A,IF($F$2="All","*",$F$2)),"") | K5: =IFERROR(SUMIFS(Cohort!$G:$G,Cohort!$B:$B,"Meta",Cohort!$A:$A,IF($F$2="All","*",$F$2))/SUMIFS(Cohort!$C:$C,Cohort!$B:$B,"Meta",Cohort!$A:$A,IF($F$2="All","*",$F$2)),"") | L5: =IFERROR(SUMIFS(Cohort!$I:$I,Cohort!$B:$B,"Meta",Cohort!$A:$A,IF($F$2="All","*",$F$2))/SUMIFS(Cohort!$C:$C,Cohort!$B:$B,"Meta",Cohort!$A:$A,IF($F$2="All","*",$F$2)),"") | M5: =IFERROR(H5/D5,"") | N5: =H5-D5
A6: OnlyFinder | B6: =SUMIFS(Data!$D:$D,Data!$A:$A,">="&$B$2,Data!$A:$A,"<="&$D$2,Data!$C:$C,"OnlyFinder",Data!$B:$B,IF($F$2="All","*",$F$2)) | C6: =SUMIFS(Data!$E:$E,Data!$A:$A,">="&$B$2,Data!$A:$A,"<="&$D$2,Data!$C:$C,"OnlyFinder",Data!$B:$B,IF($F$2="All","*",$F$2)) | D6: =B6*F6 | E6: =IFERROR(D6/C6,"") | F6: 0.75 | G6: =IFERROR(C6/B6,"") | H6: =SUMIFS(Data!$G:$G,Data!$A:$A,">="&$B$2,Data!$A:$A,"<="&$D$2,Data!$C:$C,"OnlyFinder",Data!$B:$B,IF($F$2="All","*",$F$2)) | I6: =IFERROR(SUMIFS(Cohort!$E:$E,Cohort!$B:$B,"OnlyFinder",Cohort!$A:$A,IF($F$2="All","*",$F$2))/SUMIFS(Cohort!$C:$C,Cohort!$B:$B,"OnlyFinder",Cohort!$A:$A,IF($F$2="All","*",$F$2)),"") | J6: =IFERROR(SUMIFS(Cohort!$F:$F,Cohort!$B:$B,"OnlyFinder",Cohort!$A:$A,IF($F$2="All","*",$F$2))/SUMIFS(Cohort!$C:$C,Cohort!$B:$B,"OnlyFinder",Cohort!$A:$A,IF($F$2="All","*",$F$2)),"") | K6: =IFERROR(SUMIFS(Cohort!$G:$G,Cohort!$B:$B,"OnlyFinder",Cohort!$A:$A,IF($F$2="All","*",$F$2))/SUMIFS(Cohort!$C:$C,Cohort!$B:$B,"OnlyFinder",Cohort!$A:$A,IF($F$2="All","*",$F$2)),"") | L6: =IFERROR(SUMIFS(Cohort!$I:$I,Cohort!$B:$B,"OnlyFinder",Cohort!$A:$A,IF($F$2="All","*",$F$2))/SUMIFS(Cohort!$C:$C,Cohort!$B:$B,"OnlyFinder",Cohort!$A:$A,IF($F$2="All","*",$F$2)),"") | M6: =IFERROR(H6/D6,"") | N6: =H6-D6
A7: OnlyGuider | B7: =SUMIFS(Data!$D:$D,Data!$A:$A,">="&$B$2,Data!$A:$A,"<="&$D$2,Data!$C:$C,"OnlyGuider",Data!$B:$B,IF($F$2="All","*",$F$2)) | C7: =SUMIFS(Data!$E:$E,Data!$A:$A,">="&$B$2,Data!$A:$A,"<="&$D$2,Data!$C:$C,"OnlyGuider",Data!$B:$B,IF($F$2="All","*",$F$2)) | D7: =B7*F7 | E7: =IFERROR(D7/C7,"") | F7: 0.75 | G7: =IFERROR(C7/B7,"") | H7: =SUMIFS(Data!$G:$G,Data!$A:$A,">="&$B$2,Data!$A:$A,"<="&$D$2,Data!$C:$C,"OnlyGuider",Data!$B:$B,IF($F$2="All","*",$F$2)) | I7: =IFERROR(SUMIFS(Cohort!$E:$E,Cohort!$B:$B,"OnlyGuider",Cohort!$A:$A,IF($F$2="All","*",$F$2))/SUMIFS(Cohort!$C:$C,Cohort!$B:$B,"OnlyGuider",Cohort!$A:$A,IF($F$2="All","*",$F$2)),"") | J7: =IFERROR(SUMIFS(Cohort!$F:$F,Cohort!$B:$B,"OnlyGuider",Cohort!$A:$A,IF($F$2="All","*",$F$2))/SUMIFS(Cohort!$C:$C,Cohort!$B:$B,"OnlyGuider",Cohort!$A:$A,IF($F$2="All","*",$F$2)),"") | K7: =IFERROR(SUMIFS(Cohort!$G:$G,Cohort!$B:$B,"OnlyGuider",Cohort!$A:$A,IF($F$2="All","*",$F$2))/SUMIFS(Cohort!$C:$C,Cohort!$B:$B,"OnlyGuider",Cohort!$A:$A,IF($F$2="All","*",$F$2)),"") | L7: =IFERROR(SUMIFS(Cohort!$I:$I,Cohort!$B:$B,"OnlyGuider",Cohort!$A:$A,IF($F$2="All","*",$F$2))/SUMIFS(Cohort!$C:$C,Cohort!$B:$B,"OnlyGuider",Cohort!$A:$A,IF($F$2="All","*",$F$2)),"") | M7: =IFERROR(H7/D7,"") | N7: =H7-D7
A8: OnlySeeker | B8: =SUMIFS(Data!$D:$D,Data!$A:$A,">="&$B$2,Data!$A:$A,"<="&$D$2,Data!$C:$C,"OnlySeeker",Data!$B:$B,IF($F$2="All","*",$F$2)) | C8: =SUMIFS(Data!$E:$E,Data!$A:$A,">="&$B$2,Data!$A:$A,"<="&$D$2,Data!$C:$C,"OnlySeeker",Data!$B:$B,IF($F$2="All","*",$F$2)) | D8: =B8*F8 | E8: =IFERROR(D8/C8,"") | F8: 0.75 | G8: =IFERROR(C8/B8,"") | H8: =SUMIFS(Data!$G:$G,Data!$A:$A,">="&$B$2,Data!$A:$A,"<="&$D$2,Data!$C:$C,"OnlySeeker",Data!$B:$B,IF($F$2="All","*",$F$2)) | I8: =IFERROR(SUMIFS(Cohort!$E:$E,Cohort!$B:$B,"OnlySeeker",Cohort!$A:$A,IF($F$2="All","*",$F$2))/SUMIFS(Cohort!$C:$C,Cohort!$B:$B,"OnlySeeker",Cohort!$A:$A,IF($F$2="All","*",$F$2)),"") | J8: =IFERROR(SUMIFS(Cohort!$F:$F,Cohort!$B:$B,"OnlySeeker",Cohort!$A:$A,IF($F$2="All","*",$F$2))/SUMIFS(Cohort!$C:$C,Cohort!$B:$B,"OnlySeeker",Cohort!$A:$A,IF($F$2="All","*",$F$2)),"") | K8: =IFERROR(SUMIFS(Cohort!$G:$G,Cohort!$B:$B,"OnlySeeker",Cohort!$A:$A,IF($F$2="All","*",$F$2))/SUMIFS(Cohort!$C:$C,Cohort!$B:$B,"OnlySeeker",Cohort!$A:$A,IF($F$2="All","*",$F$2)),"") | L8: =IFERROR(SUMIFS(Cohort!$I:$I,Cohort!$B:$B,"OnlySeeker",Cohort!$A:$A,IF($F$2="All","*",$F$2))/SUMIFS(Cohort!$C:$C,Cohort!$B:$B,"OnlySeeker",Cohort!$A:$A,IF($F$2="All","*",$F$2)),"") | M8: =IFERROR(H8/D8,"") | N8: =H8-D8
A9: OnlyTraffic | B9: =SUMIFS(Data!$D:$D,Data!$A:$A,">="&$B$2,Data!$A:$A,"<="&$D$2,Data!$C:$C,"OnlyTraffic",Data!$B:$B,IF($F$2="All","*",$F$2)) | C9: =SUMIFS(Data!$E:$E,Data!$A:$A,">="&$B$2,Data!$A:$A,"<="&$D$2,Data!$C:$C,"OnlyTraffic",Data!$B:$B,IF($F$2="All","*",$F$2)) | D9: =B9*F9 | E9: =IFERROR(D9/C9,"") | F9: 0.75 | G9: =IFERROR(C9/B9,"") | H9: =SUMIFS(Data!$G:$G,Data!$A:$A,">="&$B$2,Data!$A:$A,"<="&$D$2,Data!$C:$C,"OnlyTraffic",Data!$B:$B,IF($F$2="All","*",$F$2)) | I9: =IFERROR(SUMIFS(Cohort!$E:$E,Cohort!$B:$B,"OnlyTraffic",Cohort!$A:$A,IF($F$2="All","*",$F$2))/SUMIFS(Cohort!$C:$C,Cohort!$B:$B,"OnlyTraffic",Cohort!$A:$A,IF($F$2="All","*",$F$2)),"") | J9: =IFERROR(SUMIFS(Cohort!$F:$F,Cohort!$B:$B,"OnlyTraffic",Cohort!$A:$A,IF($F$2="All","*",$F$2))/SUMIFS(Cohort!$C:$C,Cohort!$B:$B,"OnlyTraffic",Cohort!$A:$A,IF($F$2="All","*",$F$2)),"") | K9: =IFERROR(SUMIFS(Cohort!$G:$G,Cohort!$B:$B,"OnlyTraffic",Cohort!$A:$A,IF($F$2="All","*",$F$2))/SUMIFS(Cohort!$C:$C,Cohort!$B:$B,"OnlyTraffic",Cohort!$A:$A,IF($F$2="All","*",$F$2)),"") | L9: =IFERROR(SUMIFS(Cohort!$I:$I,Cohort!$B:$B,"OnlyTraffic",Cohort!$A:$A,IF($F$2="All","*",$F$2))/SUMIFS(Cohort!$C:$C,Cohort!$B:$B,"OnlyTraffic",Cohort!$A:$A,IF($F$2="All","*",$F$2)),"") | M9: =IFERROR(H9/D9,"") | N9: =H9-D9
A10: TOTAL | B10: =SUMIFS(Data!$D:$D,Data!$A:$A,">="&$B$2,Data!$A:$A,"<="&$D$2,Data!$B:$B,IF($F$2="All","*",$F$2)) | C10: =SUMIFS(Data!$E:$E,Data!$A:$A,">="&$B$2,Data!$A:$A,"<="&$D$2,Data!$B:$B,IF($F$2="All","*",$F$2)) | D10: =SUM(D5:D9) | E10: =IFERROR(D10/C10,"") | F10: =IFERROR(D10/B10,"") | G10: =IFERROR(C10/B10,"") | H10: =SUMIFS(Data!$G:$G,Data!$A:$A,">="&$B$2,Data!$A:$A,"<="&$D$2,Data!$B:$B,IF($F$2="All","*",$F$2)) | I10: =IFERROR(SUMIFS(Cohort!$E:$E,Cohort!$A:$A,IF($F$2="All","*",$F$2))/SUMIFS(Cohort!$C:$C,Cohort!$A:$A,IF($F$2="All","*",$F$2)),"") | J10: =IFERROR(SUMIFS(Cohort!$F:$F,Cohort!$A:$A,IF($F$2="All","*",$F$2))/SUMIFS(Cohort!$C:$C,Cohort!$A:$A,IF($F$2="All","*",$F$2)),"") | K10: =IFERROR(SUMIFS(Cohort!$G:$G,Cohort!$A:$A,IF($F$2="All","*",$F$2))/SUMIFS(Cohort!$C:$C,Cohort!$A:$A,IF($F$2="All","*",$F$2)),"") | L10: =IFERROR(SUMIFS(Cohort!$I:$I,Cohort!$A:$A,IF($F$2="All","*",$F$2))/SUMIFS(Cohort!$C:$C,Cohort!$A:$A,IF($F$2="All","*",$F$2)),"") | M10: =IFERROR(H10/D10,"") | N10: =H10-D10
A12: DAY BY DAY (this week + the next 7 days, by platform — for the chosen creator. Type the Relevance score in yourself.)
A13: Day / Platform | B13: Clicks | C13: Fans | D13: Spend | E13: Cost Per Fan | F13: CPC | G13: CVR | H13: Attributed Revenue | I13: Total Link LTV | J13: ROAS | K13: Agency Profit | L13: Relevance
A14: =$B$2+0 | B14: =SUMIFS(Data!$D:$D,Data!$A:$A,$A14,Data!$B:$B,IF($F$2="All","*",$F$2)) | C14: =SUMIFS(Data!$E:$E,Data!$A:$A,$A14,Data!$B:$B,IF($F$2="All","*",$F$2)) | D14: =SUMIFS(Data!$F:$F,Data!$A:$A,$A14,Data!$B:$B,IF($F$2="All","*",$F$2)) | E14: =IFERROR(D14/C14,"") | F14: =IFERROR(D14/B14,"") | G14: =IFERROR(C14/B14,"") | H14: =SUMIFS(Data!$G:$G,Data!$A:$A,$A14,Data!$B:$B,IF($F$2="All","*",$F$2)) | I14: =IFERROR(H14/C14,"") | J14: =IFERROR(H14/D14,"") | K14: =H14-D14
A15: Meta | B15: =SUMIFS(Data!$D:$D,Data!$A:$A,$A14,Data!$C:$C,"Meta",Data!$B:$B,IF($F$2="All","*",$F$2)) | C15: =SUMIFS(Data!$E:$E,Data!$A:$A,$A14,Data!$C:$C,"Meta",Data!$B:$B,IF($F$2="All","*",$F$2)) | D15: =SUMIFS(Data!$F:$F,Data!$A:$A,$A14,Data!$C:$C,"Meta",Data!$B:$B,IF($F$2="All","*",$F$2)) | E15: =IFERROR(D15/C15,"") | F15: =IFERROR(D15/B15,"") | G15: =IFERROR(C15/B15,"") | H15: =SUMIFS(Data!$G:$G,Data!$A:$A,$A14,Data!$C:$C,"Meta",Data!$B:$B,IF($F$2="All","*",$F$2)) | I15: =IFERROR(H15/C15,"") | J15: =IFERROR(H15/D15,"") | K15: =H15-D15
A16: OnlyFinder | B16: =SUMIFS(Data!$D:$D,Data!$A:$A,$A14,Data!$C:$C,"OnlyFinder",Data!$B:$B,IF($F$2="All","*",$F$2)) | C16: =SUMIFS(Data!$E:$E,Data!$A:$A,$A14,Data!$C:$C,"OnlyFinder",Data!$B:$B,IF($F$2="All","*",$F$2)) | D16: =SUMIFS(Data!$F:$F,Data!$A:$A,$A14,Data!$C:$C,"OnlyFinder",Data!$B:$B,IF($F$2="All","*",$F$2)) | E16: =IFERROR(D16/C16,"") | F16: =IFERROR(D16/B16,"") | G16: =IFERROR(C16/B16,"") | H16: =SUMIFS(Data!$G:$G,Data!$A:$A,$A14,Data!$C:$C,"OnlyFinder",Data!$B:$B,IF($F$2="All","*",$F$2)) | I16: =IFERROR(H16/C16,"") | J16: =IFERROR(H16/D16,"") | K16: =H16-D16
A17: OnlyGuider | B17: =SUMIFS(Data!$D:$D,Data!$A:$A,$A14,Data!$C:$C,"OnlyGuider",Data!$B:$B,IF($F$2="All","*",$F$2)) | C17: =SUMIFS(Data!$E:$E,Data!$A:$A,$A14,Data!$C:$C,"OnlyGuider",Data!$B:$B,IF($F$2="All","*",$F$2)) | D17: =SUMIFS(Data!$F:$F,Data!$A:$A,$A14,Data!$C:$C,"OnlyGuider",Data!$B:$B,IF($F$2="All","*",$F$2)) | E17: =IFERROR(D17/C17,"") | F17: =IFERROR(D17/B17,"") | G17: =IFERROR(C17/B17,"") | H17: =SUMIFS(Data!$G:$G,Data!$A:$A,$A14,Data!$C:$C,"OnlyGuider",Data!$B:$B,IF($F$2="All","*",$F$2)) | I17: =IFERROR(H17/C17,"") | J17: =IFERROR(H17/D17,"") | K17: =H17-D17
A18: OnlySeeker | B18: =SUMIFS(Data!$D:$D,Data!$A:$A,$A14,Data!$C:$C,"OnlySeeker",Data!$B:$B,IF($F$2="All","*",$F$2)) | C18: =SUMIFS(Data!$E:$E,Data!$A:$A,$A14,Data!$C:$C,"OnlySeeker",Data!$B:$B,IF($F$2="All","*",$F$2)) | D18: =SUMIFS(Data!$F:$F,Data!$A:$A,$A14,Data!$C:$C,"OnlySeeker",Data!$B:$B,IF($F$2="All","*",$F$2)) | E18: =IFERROR(D18/C18,"") | F18: =IFERROR(D18/B18,"") | G18: =IFERROR(C18/B18,"") | H18: =SUMIFS(Data!$G:$G,Data!$A:$A,$A14,Data!$C:$C,"OnlySeeker",Data!$B:$B,IF($F$2="All","*",$F$2)) | I18: =IFERROR(H18/C18,"") | J18: =IFERROR(H18/D18,"") | K18: =H18-D18
A19: OnlyTraffic | B19: =SUMIFS(Data!$D:$D,Data!$A:$A,$A14,Data!$C:$C,"OnlyTraffic",Data!$B:$B,IF($F$2="All","*",$F$2)) | C19: =SUMIFS(Data!$E:$E,Data!$A:$A,$A14,Data!$C:$C,"OnlyTraffic",Data!$B:$B,IF($F$2="All","*",$F$2)) | D19: =SUMIFS(Data!$F:$F,Data!$A:$A,$A14,Data!$C:$C,"OnlyTraffic",Data!$B:$B,IF($F$2="All","*",$F$2)) | E19: =IFERROR(D19/C19,"") | F19: =IFERROR(D19/B19,"") | G19: =IFERROR(C19/B19,"") | H19: =SUMIFS(Data!$G:$G,Data!$A:$A,$A14,Data!$C:$C,"OnlyTraffic",Data!$B:$B,IF($F$2="All","*",$F$2)) | I19: =IFERROR(H19/C19,"") | J19: =IFERROR(H19/D19,"") | K19: =H19-D19
A20: =$B$2+1 | B20: =SUMIFS(Data!$D:$D,Data!$A:$A,$A20,Data!$B:$B,IF($F$2="All","*",$F$2)) | C20: =SUMIFS(Data!$E:$E,Data!$A:$A,$A20,Data!$B:$B,IF($F$2="All","*",$F$2)) | D20: =SUMIFS(Data!$F:$F,Data!$A:$A,$A20,Data!$B:$B,IF($F$2="All","*",$F$2)) | E20: =IFERROR(D20/C20,"") | F20: =IFERROR(D20/B20,"") | G20: =IFERROR(C20/B20,"") | H20: =SUMIFS(Data!$G:$G,Data!$A:$A,$A20,Data!$B:$B,IF($F$2="All","*",$F$2)) | I20: =IFERROR(H20/C20,"") | J20: =IFERROR(H20/D20,"") | K20: =H20-D20
A21: Meta | B21: =SUMIFS(Data!$D:$D,Data!$A:$A,$A20,Data!$C:$C,"Meta",Data!$B:$B,IF($F$2="All","*",$F$2)) | C21: =SUMIFS(Data!$E:$E,Data!$A:$A,$A20,Data!$C:$C,"Meta",Data!$B:$B,IF($F$2="All","*",$F$2)) | D21: =SUMIFS(Data!$F:$F,Data!$A:$A,$A20,Data!$C:$C,"Meta",Data!$B:$B,IF($F$2="All","*",$F$2)) | E21: =IFERROR(D21/C21,"") | F21: =IFERROR(D21/B21,"") | G21: =IFERROR(C21/B21,"") | H21: =SUMIFS(Data!$G:$G,Data!$A:$A,$A20,Data!$C:$C,"Meta",Data!$B:$B,IF($F$2="All","*",$F$2)) | I21: =IFERROR(H21/C21,"") | J21: =IFERROR(H21/D21,"") | K21: =H21-D21
A22: OnlyFinder | B22: =SUMIFS(Data!$D:$D,Data!$A:$A,$A20,Data!$C:$C,"OnlyFinder",Data!$B:$B,IF($F$2="All","*",$F$2)) | C22: =SUMIFS(Data!$E:$E,Data!$A:$A,$A20,Data!$C:$C,"OnlyFinder",Data!$B:$B,IF($F$2="All","*",$F$2)) | D22: =SUMIFS(Data!$F:$F,Data!$A:$A,$A20,Data!$C:$C,"OnlyFinder",Data!$B:$B,IF($F$2="All","*",$F$2)) | E22: =IFERROR(D22/C22,"") | F22: =IFERROR(D22/B22,"") | G22: =IFERROR(C22/B22,"") | H22: =SUMIFS(Data!$G:$G,Data!$A:$A,$A20,Data!$C:$C,"OnlyFinder",Data!$B:$B,IF($F$2="All","*",$F$2)) | I22: =IFERROR(H22/C22,"") | J22: =IFERROR(H22/D22,"") | K22: =H22-D22
A23: OnlyGuider | B23: =SUMIFS(Data!$D:$D,Data!$A:$A,$A20,Data!$C:$C,"OnlyGuider",Data!$B:$B,IF($F$2="All","*",$F$2)) | C23: =SUMIFS(Data!$E:$E,Data!$A:$A,$A20,Data!$C:$C,"OnlyGuider",Data!$B:$B,IF($F$2="All","*",$F$2)) | D23: =SUMIFS(Data!$F:$F,Data!$A:$A,$A20,Data!$C:$C,"OnlyGuider",Data!$B:$B,IF($F$2="All","*",$F$2)) | E23: =IFERROR(D23/C23,"") | F23: =IFERROR(D23/B23,"") | G23: =IFERROR(C23/B23,"") | H23: =SUMIFS(Data!$G:$G,Data!$A:$A,$A20,Data!$C:$C,"OnlyGuider",Data!$B:$B,IF($F$2="All","*",$F$2)) | I23: =IFERROR(H23/C23,"") | J23: =IFERROR(H23/D23,"") | K23: =H23-D23
A24: OnlySeeker | B24: =SUMIFS(Data!$D:$D,Data!$A:$A,$A20,Data!$C:$C,"OnlySeeker",Data!$B:$B,IF($F$2="All","*",$F$2)) | C24: =SUMIFS(Data!$E:$E,Data!$A:$A,$A20,Data!$C:$C,"OnlySeeker",Data!$B:$B,IF($F$2="All","*",$F$2)) | D24: =SUMIFS(Data!$F:$F,Data!$A:$A,$A20,Data!$C:$C,"OnlySeeker",Data!$B:$B,IF($F$2="All","*",$F$2)) | E24: =IFERROR(D24/C24,"") | F24: =IFERROR(D24/B24,"") | G24: =IFERROR(C24/B24,"") | H24: =SUMIFS(Data!$G:$G,Data!$A:$A,$A20,Data!$C:$C,"OnlySeeker",Data!$B:$B,IF($F$2="All","*",$F$2)) | I24: =IFERROR(H24/C24,"") | J24: =IFERROR(H24/D24,"") | K24: =H24-D24
A25: OnlyTraffic | B25: =SUMIFS(Data!$D:$D,Data!$A:$A,$A20,Data!$C:$C,"OnlyTraffic",Data!$B:$B,IF($F$2="All","*",$F$2)) | C25: =SUMIFS(Data!$E:$E,Data!$A:$A,$A20,Data!$C:$C,"OnlyTraffic",Data!$B:$B,IF($F$2="All","*",$F$2)) | D25: =SUMIFS(Data!$F:$F,Data!$A:$A,$A20,Data!$C:$C,"OnlyTraffic",Data!$B:$B,IF($F$2="All","*",$F$2)) | E25: =IFERROR(D25/C25,"") | F25: =IFERROR(D25/B25,"") | G25: =IFERROR(C25/B25,"") | H25: =SUMIFS(Data!$G:$G,Data!$A:$A,$A20,Data!$C:$C,"OnlyTraffic",Data!$B:$B,IF($F$2="All","*",$F$2)) | I25: =IFERROR(H25/C25,"") | J25: =IFERROR(H25/D25,"") | K25: =H25-D25
A26: =$B$2+2 | B26: =SUMIFS(Data!$D:$D,Data!$A:$A,$A26,Data!$B:$B,IF($F$2="All","*",$F$2)) | C26: =SUMIFS(Data!$E:$E,Data!$A:$A,$A26,Data!$B:$B,IF($F$2="All","*",$F$2)) | D26: =SUMIFS(Data!$F:$F,Data!$A:$A,$A26,Data!$B:$B,IF($F$2="All","*",$F$2)) | E26: =IFERROR(D26/C26,"") | F26: =IFERROR(D26/B26,"") | G26: =IFERROR(C26/B26,"") | H26: =SUMIFS(Data!$G:$G,Data!$A:$A,$A26,Data!$B:$B,IF($F$2="All","*",$F$2)) | I26: =IFERROR(H26/C26,"") | J26: =IFERROR(H26/D26,"") | K26: =H26-D26
A27: Meta | B27: =SUMIFS(Data!$D:$D,Data!$A:$A,$A26,Data!$C:$C,"Meta",Data!$B:$B,IF($F$2="All","*",$F$2)) | C27: =SUMIFS(Data!$E:$E,Data!$A:$A,$A26,Data!$C:$C,"Meta",Data!$B:$B,IF($F$2="All","*",$F$2)) | D27: =SUMIFS(Data!$F:$F,Data!$A:$A,$A26,Data!$C:$C,"Meta",Data!$B:$B,IF($F$2="All","*",$F$2)) | E27: =IFERROR(D27/C27,"") | F27: =IFERROR(D27/B27,"") | G27: =IFERROR(C27/B27,"") | H27: =SUMIFS(Data!$G:$G,Data!$A:$A,$A26,Data!$C:$C,"Meta",Data!$B:$B,IF($F$2="All","*",$F$2)) | I27: =IFERROR(H27/C27,"") | J27: =IFERROR(H27/D27,"") | K27: =H27-D27
A28: OnlyFinder | B28: =SUMIFS(Data!$D:$D,Data!$A:$A,$A26,Data!$C:$C,"OnlyFinder",Data!$B:$B,IF($F$2="All","*",$F$2)) | C28: =SUMIFS(Data!$E:$E,Data!$A:$A,$A26,Data!$C:$C,"OnlyFinder",Data!$B:$B,IF($F$2="All","*",$F$2)) | D28: =SUMIFS(Data!$F:$F,Data!$A:$A,$A26,Data!$C:$C,"OnlyFinder",Data!$B:$B,IF($F$2="All","*",$F$2)) | E28: =IFERROR(D28/C28,"") | F28: =IFERROR(D28/B28,"") | G28: =IFERROR(C28/B28,"") | H28: =SUMIFS(Data!$G:$G,Data!$A:$A,$A26,Data!$C:$C,"OnlyFinder",Data!$B:$B,IF($F$2="All","*",$F$2)) | I28: =IFERROR(H28/C28,"") | J28: =IFERROR(H28/D28,"") | K28: =H28-D28
A29: OnlyGuider | B29: =SUMIFS(Data!$D:$D,Data!$A:$A,$A26,Data!$C:$C,"OnlyGuider",Data!$B:$B,IF($F$2="All","*",$F$2)) | C29: =SUMIFS(Data!$E:$E,Data!$A:$A,$A26,Data!$C:$C,"OnlyGuider",Data!$B:$B,IF($F$2="All","*",$F$2)) | D29: =SUMIFS(Data!$F:$F,Data!$A:$A,$A26,Data!$C:$C,"OnlyGuider",Data!$B:$B,IF($F$2="All","*",$F$2)) | E29: =IFERROR(D29/C29,"") | F29: =IFERROR(D29/B29,"") | G29: =IFERROR(C29/B29,"") | H29: =SUMIFS(Data!$G:$G,Data!$A:$A,$A26,Data!$C:$C,"OnlyGuider",Data!$B:$B,IF($F$2="All","*",$F$2)) | I29: =IFERROR(H29/C29,"") | J29: =IFERROR(H29/D29,"") | K29: =H29-D29
A30: OnlySeeker | B30: =SUMIFS(Data!$D:$D,Data!$A:$A,$A26,Data!$C:$C,"OnlySeeker",Data!$B:$B,IF($F$2="All","*",$F$2)) | C30: =SUMIFS(Data!$E:$E,Data!$A:$A,$A26,Data!$C:$C,"OnlySeeker",Data!$B:$B,IF($F$2="All","*",$F$2)) | D30: =SUMIFS(Data!$F:$F,Data!$A:$A,$A26,Data!$C:$C,"OnlySeeker",Data!$B:$B,IF($F$2="All","*",$F$2)) | E30: =IFERROR(D30/C30,"") | F30: =IFERROR(D30/B30,"") | G30: =IFERROR(C30/B30,"") | H30: =SUMIFS(Data!$G:$G,Data!$A:$A,$A26,Data!$C:$C,"OnlySeeker",Data!$B:$B,IF($F$2="All","*",$F$2)) | I30: =IFERROR(H30/C30,"") | J30: =IFERROR(H30/D30,"") | K30: =H30-D30
A31: OnlyTraffic | B31: =SUMIFS(Data!$D:$D,Data!$A:$A,$A26,Data!$C:$C,"OnlyTraffic",Data!$B:$B,IF($F$2="All","*",$F$2)) | C31: =SUMIFS(Data!$E:$E,Data!$A:$A,$A26,Data!$C:$C,"OnlyTraffic",Data!$B:$B,IF($F$2="All","*",$F$2)) | D31: =SUMIFS(Data!$F:$F,Data!$A:$A,$A26,Data!$C:$C,"OnlyTraffic",Data!$B:$B,IF($F$2="All","*",$F$2)) | E31: =IFERROR(D31/C31,"") | F31: =IFERROR(D31/B31,"") | G31: =IFERROR(C31/B31,"") | H31: =SUMIFS(Data!$G:$G,Data!$A:$A,$A26,Data!$C:$C,"OnlyTraffic",Data!$B:$B,IF($F$2="All","*",$F$2)) | I31: =IFERROR(H31/C31,"") | J31: =IFERROR(H31/D31,"") | K31: =H31-D31
A32: =$B$2+3 | B32: =SUMIFS(Data!$D:$D,Data!$A:$A,$A32,Data!$B:$B,IF($F$2="All","*",$F$2)) | C32: =SUMIFS(Data!$E:$E,Data!$A:$A,$A32,Data!$B:$B,IF($F$2="All","*",$F$2)) | D32: =SUMIFS(Data!$F:$F,Data!$A:$A,$A32,Data!$B:$B,IF($F$2="All","*",$F$2)) | E32: =IFERROR(D32/C32,"") | F32: =IFERROR(D32/B32,"") | G32: =IFERROR(C32/B32,"") | H32: =SUMIFS(Data!$G:$G,Data!$A:$A,$A32,Data!$B:$B,IF($F$2="All","*",$F$2)) | I32: =IFERROR(H32/C32,"") | J32: =IFERROR(H32/D32,"") | K32: =H32-D32
A33: Meta | B33: =SUMIFS(Data!$D:$D,Data!$A:$A,$A32,Data!$C:$C,"Meta",Data!$B:$B,IF($F$2="All","*",$F$2)) | C33: =SUMIFS(Data!$E:$E,Data!$A:$A,$A32,Data!$C:$C,"Meta",Data!$B:$B,IF($F$2="All","*",$F$2)) | D33: =SUMIFS(Data!$F:$F,Data!$A:$A,$A32,Data!$C:$C,"Meta",Data!$B:$B,IF($F$2="All","*",$F$2)) | E33: =IFERROR(D33/C33,"") | F33: =IFERROR(D33/B33,"") | G33: =IFERROR(C33/B33,"") | H33: =SUMIFS(Data!$G:$G,Data!$A:$A,$A32,Data!$C:$C,"Meta",Data!$B:$B,IF($F$2="All","*",$F$2)) | I33: =IFERROR(H33/C33,"") | J33: =IFERROR(H33/D33,"") | K33: =H33-D33
A34: OnlyFinder | B34: =SUMIFS(Data!$D:$D,Data!$A:$A,$A32,Data!$C:$C,"OnlyFinder",Data!$B:$B,IF($F$2="All","*",$F$2)) | C34: =SUMIFS(Data!$E:$E,Data!$A:$A,$A32,Data!$C:$C,"OnlyFinder",Data!$B:$B,IF($F$2="All","*",$F$2)) | D34: =SUMIFS(Data!$F:$F,Data!$A:$A,$A32,Data!$C:$C,"OnlyFinder",Data!$B:$B,IF($F$2="All","*",$F$2)) | E34: =IFERROR(D34/C34,"") | F34: =IFERROR(D34/B34,"") | G34: =IFERROR(C34/B34,"") | H34: =SUMIFS(Data!$G:$G,Data!$A:$A,$A32,Data!$C:$C,"OnlyFinder",Data!$B:$B,IF($F$2="All","*",$F$2)) | I34: =IFERROR(H34/C34,"") | J34: =IFERROR(H34/D34,"") | K34: =H34-D34
A35: OnlyGuider | B35: =SUMIFS(Data!$D:$D,Data!$A:$A,$A32,Data!$C:$C,"OnlyGuider",Data!$B:$B,IF($F$2="All","*",$F$2)) | C35: =SUMIFS(Data!$E:$E,Data!$A:$A,$A32,Data!$C:$C,"OnlyGuider",Data!$B:$B,IF($F$2="All","*",$F$2)) | D35: =SUMIFS(Data!$F:$F,Data!$A:$A,$A32,Data!$C:$C,"OnlyGuider",Data!$B:$B,IF($F$2="All","*",$F$2)) | E35: =IFERROR(D35/C35,"") | F35: =IFERROR(D35/B35,"") | G35: =IFERROR(C35/B35,"") | H35: =SUMIFS(Data!$G:$G,Data!$A:$A,$A32,Data!$C:$C,"OnlyGuider",Data!$B:$B,IF($F$2="All","*",$F$2)) | I35: =IFERROR(H35/C35,"") | J35: =IFERROR(H35/D35,"") | K35: =H35-D35
A36: OnlySeeker | B36: =SUMIFS(Data!$D:$D,Data!$A:$A,$A32,Data!$C:$C,"OnlySeeker",Data!$B:$B,IF($F$2="All","*",$F$2)) | C36: =SUMIFS(Data!$E:$E,Data!$A:$A,$A32,Data!$C:$C,"OnlySeeker",Data!$B:$B,IF($F$2="All","*",$F$2)) | D36: =SUMIFS(Data!$F:$F,Data!$A:$A,$A32,Data!$C:$C,"OnlySeeker",Data!$B:$B,IF($F$2="All","*",$F$2)) | E36: =IFERROR(D36/C36,"") | F36: =IFERROR(D36/B36,"") | G36: =IFERROR(C36/B36,"") | H36: =SUMIFS(Data!$G:$G,Data!$A:$A,$A32,Data!$C:$C,"OnlySeeker",Data!$B:$B,IF($F$2="All","*",$F$2)) | I36: =IFERROR(H36/C36,"") | J36: =IFERROR(H36/D36,"") | K36: =H36-D36
A37: OnlyTraffic | B37: =SUMIFS(Data!$D:$D,Data!$A:$A,$A32,Data!$C:$C,"OnlyTraffic",Data!$B:$B,IF($F$2="All","*",$F$2)) | C37: =SUMIFS(Data!$E:$E,Data!$A:$A,$A32,Data!$C:$C,"OnlyTraffic",Data!$B:$B,IF($F$2="All","*",$F$2)) | D37: =SUMIFS(Data!$F:$F,Data!$A:$A,$A32,Data!$C:$C,"OnlyTraffic",Data!$B:$B,IF($F$2="All","*",$F$2)) | E37: =IFERROR(D37/C37,"") | F37: =IFERROR(D37/B37,"") | G37: =IFERROR(C37/B37,"") | H37: =SUMIFS(Data!$G:$G,Data!$A:$A,$A32,Data!$C:$C,"OnlyTraffic",Data!$B:$B,IF($F$2="All","*",$F$2)) | I37: =IFERROR(H37/C37,"") | J37: =IFERROR(H37/D37,"") | K37: =H37-D37
A38: =$B$2+4 | B38: =SUMIFS(Data!$D:$D,Data!$A:$A,$A38,Data!$B:$B,IF($F$2="All","*",$F$2)) | C38: =SUMIFS(Data!$E:$E,Data!$A:$A,$A38,Data!$B:$B,IF($F$2="All","*",$F$2)) | D38: =SUMIFS(Data!$F:$F,Data!$A:$A,$A38,Data!$B:$B,IF($F$2="All","*",$F$2)) | E38: =IFERROR(D38/C38,"") | F38: =IFERROR(D38/B38,"") | G38: =IFERROR(C38/B38,"") | H38: =SUMIFS(Data!$G:$G,Data!$A:$A,$A38,Data!$B:$B,IF($F$2="All","*",$F$2)) | I38: =IFERROR(H38/C38,"") | J38: =IFERROR(H38/D38,"") | K38: =H38-D38
A39: Meta | B39: =SUMIFS(Data!$D:$D,Data!$A:$A,$A38,Data!$C:$C,"Meta",Data!$B:$B,IF($F$2="All","*",$F$2)) | C39: =SUMIFS(Data!$E:$E,Data!$A:$A,$A38,Data!$C:$C,"Meta",Data!$B:$B,IF($F$2="All","*",$F$2)) | D39: =SUMIFS(Data!$F:$F,Data!$A:$A,$A38,Data!$C:$C,"Meta",Data!$B:$B,IF($F$2="All","*",$F$2)) | E39: =IFERROR(D39/C39,"") | F39: =IFERROR(D39/B39,"") | G39: =IFERROR(C39/B39,"") | H39: =SUMIFS(Data!$G:$G,Data!$A:$A,$A38,Data!$C:$C,"Meta",Data!$B:$B,IF($F$2="All","*",$F$2)) | I39: =IFERROR(H39/C39,"") | J39: =IFERROR(H39/D39,"") | K39: =H39-D39
A40: OnlyFinder | B40: =SUMIFS(Data!$D:$D,Data!$A:$A,$A38,Data!$C:$C,"OnlyFinder",Data!$B:$B,IF($F$2="All","*",$F$2)) | C40: =SUMIFS(Data!$E:$E,Data!$A:$A,$A38,Data!$C:$C,"OnlyFinder",Data!$B:$B,IF($F$2="All","*",$F$2)) | D40: =SUMIFS(Data!$F:$F,Data!$A:$A,$A38,Data!$C:$C,"OnlyFinder",Data!$B:$B,IF($F$2="All","*",$F$2)) | E40: =IFERROR(D40/C40,"") | F40: =IFERROR(D40/B40,"") | G40: =IFERROR(C40/B40,"") | H40: =SUMIFS(Data!$G:$G,Data!$A:$A,$A38,Data!$C:$C,"OnlyFinder",Data!$B:$B,IF($F$2="All","*",$F$2)) | I40: =IFERROR(H40/C40,"") | J40: =IFERROR(H40/D40,"") | K40: =H40-D40
A41: OnlyGuider | B41: =SUMIFS(Data!$D:$D,Data!$A:$A,$A38,Data!$C:$C,"OnlyGuider",Data!$B:$B,IF($F$2="All","*",$F$2)) | C41: =SUMIFS(Data!$E:$E,Data!$A:$A,$A38,Data!$C:$C,"OnlyGuider",Data!$B:$B,IF($F$2="All","*",$F$2)) | D41: =SUMIFS(Data!$F:$F,Data!$A:$A,$A38,Data!$C:$C,"OnlyGuider",Data!$B:$B,IF($F$2="All","*",$F$2)) | E41: =IFERROR(D41/C41,"") | F41: =IFERROR(D41/B41,"") | G41: =IFERROR(C41/B41,"") | H41: =SUMIFS(Data!$G:$G,Data!$A:$A,$A38,Data!$C:$C,"OnlyGuider",Data!$B:$B,IF($F$2="All","*",$F$2)) | I41: =IFERROR(H41/C41,"") | J41: =IFERROR(H41/D41,"") | K41: =H41-D41
...

Sheet Time to Profit
A1: UNCVRD — TIME TO PROFIT / BREAK-EVEN (per platform · lifetime value of the fans each platform brought)
A2: Creator ▸ | B2: All | D2: Set each platform's REAL Cost / Click in the yellow column (D) below — Meta, OnlyFinder etc. can each have their own rate →
A3: ARPS = revenue each fan has spent by that age. Profitable when ARPS All ≥ Cost / Sub. Green margin = you make money.
A4: Platform | B4: Subscribers | C4: Clicks | D4: Cost / Click | E4: Cost / Promo | F4: Cost / Sub | G4: ARPS 48h | H4: ARPS 7d | I4: ARPS 14d | J4: ARPS 30d | K4: ARPS All (Rev/Sub) | L4: Margin / Sub | M4: Break-even by
A5: Meta | B5: =SUMIFS(Cohort!$C:$C,Cohort!$B:$B,"Meta",Cohort!$A:$A,IF($B$2="All","*",$B$2)) | C5: =SUMIFS(Cohort!$D:$D,Cohort!$B:$B,"Meta",Cohort!$A:$A,IF($B$2="All","*",$B$2)) | D5: 0.75 | E5: =D5*C5 | F5: =IFERROR(E5/B5,"") | G5: =IFERROR((SUMIFS(Cohort!$E:$E,Cohort!$B:$B,"Meta",Cohort!$A:$A,IF($B$2="All","*",$B$2)))/B5,"") | H5: =IFERROR((SUMIFS(Cohort!$F:$F,Cohort!$B:$B,"Meta",Cohort!$A:$A,IF($B$2="All","*",$B$2)))/B5,"") | I5: =IFERROR((SUMIFS(Cohort!$G:$G,Cohort!$B:$B,"Meta",Cohort!$A:$A,IF($B$2="All","*",$B$2)))/B5,"") | J5: =IFERROR((SUMIFS(Cohort!$I:$I,Cohort!$B:$B,"Meta",Cohort!$A:$A,IF($B$2="All","*",$B$2)))/B5,"") | K5: =IFERROR((SUMIFS(Cohort!$J:$J,Cohort!$B:$B,"Meta",Cohort!$A:$A,IF($B$2="All","*",$B$2)))/B5,"") | L5: =IFERROR(K5-F5,"") | M5: =IF(B5=0,"",IF(G5>=F5,"by 48h",IF(H5>=F5,"by 7d",IF(I5>=F5,"by 14d",IF(J5>=F5,"by 30d",IF(K5>=F5,"after 30d","not yet"))))))
A6: OnlyFinder | B6: =SUMIFS(Cohort!$C:$C,Cohort!$B:$B,"OnlyFinder",Cohort!$A:$A,IF($B$2="All","*",$B$2)) | C6: =SUMIFS(Cohort!$D:$D,Cohort!$B:$B,"OnlyFinder",Cohort!$A:$A,IF($B$2="All","*",$B$2)) | D6: 0.75 | E6: =D6*C6 | F6: =IFERROR(E6/B6,"") | G6: =IFERROR((SUMIFS(Cohort!$E:$E,Cohort!$B:$B,"OnlyFinder",Cohort!$A:$A,IF($B$2="All","*",$B$2)))/B6,"") | H6: =IFERROR((SUMIFS(Cohort!$F:$F,Cohort!$B:$B,"OnlyFinder",Cohort!$A:$A,IF($B$2="All","*",$B$2)))/B6,"") | I6: =IFERROR((SUMIFS(Cohort!$G:$G,Cohort!$B:$B,"OnlyFinder",Cohort!$A:$A,IF($B$2="All","*",$B$2)))/B6,"") | J6: =IFERROR((SUMIFS(Cohort!$I:$I,Cohort!$B:$B,"OnlyFinder",Cohort!$A:$A,IF($B$2="All","*",$B$2)))/B6,"") | K6: =IFERROR((SUMIFS(Cohort!$J:$J,Cohort!$B:$B,"OnlyFinder",Cohort!$A:$A,IF($B$2="All","*",$B$2)))/B6,"") | L6: =IFERROR(K6-F6,"") | M6: =IF(B6=0,"",IF(G6>=F6,"by 48h",IF(H6>=F6,"by 7d",IF(I6>=F6,"by 14d",IF(J6>=F6,"by 30d",IF(K6>=F6,"after 30d","not yet"))))))
A7: OnlyGuider | B7: =SUMIFS(Cohort!$C:$C,Cohort!$B:$B,"OnlyGuider",Cohort!$A:$A,IF($B$2="All","*",$B$2)) | C7: =SUMIFS(Cohort!$D:$D,Cohort!$B:$B,"OnlyGuider",Cohort!$A:$A,IF($B$2="All","*",$B$2)) | D7: 0.75 | E7: =D7*C7 | F7: =IFERROR(E7/B7,"") | G7: =IFERROR((SUMIFS(Cohort!$E:$E,Cohort!$B:$B,"OnlyGuider",Cohort!$A:$A,IF($B$2="All","*",$B$2)))/B7,"") | H7: =IFERROR((SUMIFS(Cohort!$F:$F,Cohort!$B:$B,"OnlyGuider",Cohort!$A:$A,IF($B$2="All","*",$B$2)))/B7,"") | I7: =IFERROR((SUMIFS(Cohort!$G:$G,Cohort!$B:$B,"OnlyGuider",Cohort!$A:$A,IF($B$2="All","*",$B$2)))/B7,"") | J7: =IFERROR((SUMIFS(Cohort!$I:$I,Cohort!$B:$B,"OnlyGuider",Cohort!$A:$A,IF($B$2="All","*",$B$2)))/B7,"") | K7: =IFERROR((SUMIFS(Cohort!$J:$J,Cohort!$B:$B,"OnlyGuider",Cohort!$A:$A,IF($B$2="All","*",$B$2)))/B7,"") | L7: =IFERROR(K7-F7,"") | M7: =IF(B7=0,"",IF(G7>=F7,"by 48h",IF(H7>=F7,"by 7d",IF(I7>=F7,"by 14d",IF(J7>=F7,"by 30d",IF(K7>=F7,"after 30d","not yet"))))))
A8: OnlySeeker | B8: =SUMIFS(Cohort!$C:$C,Cohort!$B:$B,"OnlySeeker",Cohort!$A:$A,IF($B$2="All","*",$B$2)) | C8: =SUMIFS(Cohort!$D:$D,Cohort!$B:$B,"OnlySeeker",Cohort!$A:$A,IF($B$2="All","*",$B$2)) | D8: 0.75 | E8: =D8*C8 | F8: =IFERROR(E8/B8,"") | G8: =IFERROR((SUMIFS(Cohort!$E:$E,Cohort!$B:$B,"OnlySeeker",Cohort!$A:$A,IF($B$2="All","*",$B$2)))/B8,"") | H8: =IFERROR((SUMIFS(Cohort!$F:$F,Cohort!$B:$B,"OnlySeeker",Cohort!$A:$A,IF($B$2="All","*",$B$2)))/B8,"") | I8: =IFERROR((SUMIFS(Cohort!$G:$G,Cohort!$B:$B,"OnlySeeker",Cohort!$A:$A,IF($B$2="All","*",$B$2)))/B8,"") | J8: =IFERROR((SUMIFS(Cohort!$I:$I,Cohort!$B:$B,"OnlySeeker",Cohort!$A:$A,IF($B$2="All","*",$B$2)))/B8,"") | K8: =IFERROR((SUMIFS(Cohort!$J:$J,Cohort!$B:$B,"OnlySeeker",Cohort!$A:$A,IF($B$2="All","*",$B$2)))/B8,"") | L8: =IFERROR(K8-F8,"") | M8: =IF(B8=0,"",IF(G8>=F8,"by 48h",IF(H8>=F8,"by 7d",IF(I8>=F8,"by 14d",IF(J8>=F8,"by 30d",IF(K8>=F8,"after 30d","not yet"))))))
A9: OnlyTraffic | B9: =SUMIFS(Cohort!$C:$C,Cohort!$B:$B,"OnlyTraffic",Cohort!$A:$A,IF($B$2="All","*",$B$2)) | C9: =SUMIFS(Cohort!$D:$D,Cohort!$B:$B,"OnlyTraffic",Cohort!$A:$A,IF($B$2="All","*",$B$2)) | D9: 0.75 | E9: =D9*C9 | F9: =IFERROR(E9/B9,"") | G9: =IFERROR((SUMIFS(Cohort!$E:$E,Cohort!$B:$B,"OnlyTraffic",Cohort!$A:$A,IF($B$2="All","*",$B$2)))/B9,"") | H9: =IFERROR((SUMIFS(Cohort!$F:$F,Cohort!$B:$B,"OnlyTraffic",Cohort!$A:$A,IF($B$2="All","*",$B$2)))/B9,"") | I9: =IFERROR((SUMIFS(Cohort!$G:$G,Cohort!$B:$B,"OnlyTraffic",Cohort!$A:$A,IF($B$2="All","*",$B$2)))/B9,"") | J9: =IFERROR((SUMIFS(Cohort!$I:$I,Cohort!$B:$B,"OnlyTraffic",Cohort!$A:$A,IF($B$2="All","*",$B$2)))/B9,"") | K9: =IFERROR((SUMIFS(Cohort!$J:$J,Cohort!$B:$B,"OnlyTraffic",Cohort!$A:$A,IF($B$2="All","*",$B$2)))/B9,"") | L9: =IFERROR(K9-F9,"") | M9: =IF(B9=0,"",IF(G9>=F9,"by 48h",IF(H9>=F9,"by 7d",IF(I9>=F9,"by 14d",IF(J9>=F9,"by 30d",IF(K9>=F9,"after 30d","not yet"))))))
A10: TOTAL | B10: =SUMIFS(Cohort!$C:$C,Cohort!$A:$A,IF($B$2="All","*",$B$2)) | C10: =SUMIFS(Cohort!$D:$D,Cohort!$A:$A,IF($B$2="All","*",$B$2)) | D10: =IFERROR(E10/C10,"") | E10: =SUM(E5:E9) | F10: =IFERROR(E10/B10,"") | G10: =IFERROR((SUMIFS(Cohort!$E:$E,Cohort!$A:$A,IF($B$2="All","*",$B$2)))/B10,"") | H10: =IFERROR((SUMIFS(Cohort!$F:$F,Cohort!$A:$A,IF($B$2="All","*",$B$2)))/B10,"") | I10: =IFERROR((SUMIFS(Cohort!$G:$G,Cohort!$A:$A,IF($B$2="All","*",$B$2)))/B10,"") | J10: =IFERROR((SUMIFS(Cohort!$I:$I,Cohort!$A:$A,IF($B$2="All","*",$B$2)))/B10,"") | K10: =IFERROR((SUMIFS(Cohort!$J:$J,Cohort!$A:$A,IF($B$2="All","*",$B$2)))/B10,"") | L10: =IFERROR(K10-F10,"") | M10: =IF(B10=0,"",IF(G10>=F10,"by 48h",IF(H10>=F10,"by 7d",IF(I10>=F10,"by 14d",IF(J10>=F10,"by 30d",IF(K10>=F10,"after 30d","not yet"))))))

Sheet Weekly History
A1: UNCVRD — WEEKLY HISTORY (every week saved · Fri → Thu)
A2: Creator ▸ | B2: All
A3: Week (Fri start) | B3: Clicks | C3: Fans | D3: Spend | E3: CPC | F3: CVR | G3: Attributed Revenue | H3: ROAS | I3: Agency Profit
A4: 46199 | B4: =SUMIFS(Data!$D:$D,Data!$A:$A,">="&$A4,Data!$A:$A,"<="&($A4+6),Data!$B:$B,IF($B$2="All","*",$B$2)) | C4: =SUMIFS(Data!$E:$E,Data!$A:$A,">="&$A4,Data!$A:$A,"<="&($A4+6),Data!$B:$B,IF($B$2="All","*",$B$2)) | D4: =SUMIFS(Data!$F:$F,Data!$A:$A,">="&$A4,Data!$A:$A,"<="&($A4+6),Data!$B:$B,IF($B$2="All","*",$B$2)) | E4: =IFERROR(D4/B4,"") | F4: =IFERROR(C4/B4,"") | G4: =SUMIFS(Data!$G:$G,Data!$A:$A,">="&$A4,Data!$A:$A,"<="&($A4+6),Data!$B:$B,IF($B$2="All","*",$B$2)) | H4: =IFERROR(G4/D4,"") | I4: =G4-D4
A5: 46192 | B5: =SUMIFS(Data!$D:$D,Data!$A:$A,">="&$A5,Data!$A:$A,"<="&($A5+6),Data!$B:$B,IF($B$2="All","*",$B$2)) | C5: =SUMIFS(Data!$E:$E,Data!$A:$A,">="&$A5,Data!$A:$A,"<="&($A5+6),Data!$B:$B,IF($B$2="All","*",$B$2)) | D5: =SUMIFS(Data!$F:$F,Data!$A:$A,">="&$A5,Data!$A:$A,"<="&($A5+6),Data!$B:$B,IF($B$2="All","*",$B$2)) | E5: =IFERROR(D5/B5,"") | F5: =IFERROR(C5/B5,"") | G5: =SUMIFS(Data!$G:$G,Data!$A:$A,">="&$A5,Data!$A:$A,"<="&($A5+6),Data!$B:$B,IF($B$2="All","*",$B$2)) | H5: =IFERROR(G5/D5,"") | I5: =G5-D5
A6: 46185 | B6: =SUMIFS(Data!$D:$D,Data!$A:$A,">="&$A6,Data!$A:$A,"<="&($A6+6),Data!$B:$B,IF($B$2="All","*",$B$2)) | C6: =SUMIFS(Data!$E:$E,Data!$A:$A,">="&$A6,Data!$A:$A,"<="&($A6+6),Data!$B:$B,IF($B$2="All","*",$B$2)) | D6: =SUMIFS(Data!$F:$F,Data!$A:$A,">="&$A6,Data!$A:$A,"<="&($A6+6),Data!$B:$B,IF($B$2="All","*",$B$2)) | E6: =IFERROR(D6/B6,"") | F6: =IFERROR(C6/B6,"") | G6: =SUMIFS(Data!$G:$G,Data!$A:$A,">="&$A6,Data!$A:$A,"<="&($A6+6),Data!$B:$B,IF($B$2="All","*",$B$2)) | H6: =IFERROR(G6/D6,"") | I6: =G6-D6
A7: 46178 | B7: =SUMIFS(Data!$D:$D,Data!$A:$A,">="&$A7,Data!$A:$A,"<="&($A7+6),Data!$B:$B,IF($B$2="All","*",$B$2)) | C7: =SUMIFS(Data!$E:$E,Data!$A:$A,">="&$A7,Data!$A:$A,"<="&($A7+6),Data!$B:$B,IF($B$2="All","*",$B$2)) | D7: =SUMIFS(Data!$F:$F,Data!$A:$A,">="&$A7,Data!$A:$A,"<="&($A7+6),Data!$B:$B,IF($B$2="All","*",$B$2)) | E7: =IFERROR(D7/B7,"") | F7: =IFERROR(C7/B7,"") | G7: =SUMIFS(Data!$G:$G,Data!$A:$A,">="&$A7,Data!$A:$A,"<="&($A7+6),Data!$B:$B,IF($B$2="All","*",$B$2)) | H7: =IFERROR(G7/D7,"") | I7: =G7-D7
A8: 46171 | B8: =SUMIFS(Data!$D:$D,Data!$A:$A,">="&$A8,Data!$A:$A,"<="&($A8+6),Data!$B:$B,IF($B$2="All","*",$B$2)) | C8: =SUMIFS(Data!$E:$E,Data!$A:$A,">="&$A8,Data!$A:$A,"<="&($A8+6),Data!$B:$B,IF($B$2="All","*",$B$2)) | D8: =SUMIFS(Data!$F:$F,Data!$A:$A,">="&$A8,Data!$A:$A,"<="&($A8+6),Data!$B:$B,IF($B$2="All","*",$B$2)) | E8: =IFERROR(D8/B8,"") | F8: =IFERROR(C8/B8,"") | G8: =SUMIFS(Data!$G:$G,Data!$A:$A,">="&$A8,Data!$A:$A,"<="&($A8+6),Data!$B:$B,IF($B$2="All","*",$B$2)) | H8: =IFERROR(G8/D8,"") | I8: =G8-D8
A9: 46164 | B9: =SUMIFS(Data!$D:$D,Data!$A:$A,">="&$A9,Data!$A:$A,"<="&($A9+6),Data!$B:$B,IF($B$2="All","*",$B$2)) | C9: =SUMIFS(Data!$E:$E,Data!$A:$A,">="&$A9,Data!$A:$A,"<="&($A9+6),Data!$B:$B,IF($B$2="All","*",$B$2)) | D9: =SUMIFS(Data!$F:$F,Data!$A:$A,">="&$A9,Data!$A:$A,"<="&($A9+6),Data!$B:$B,IF($B$2="All","*",$B$2)) | E9: =IFERROR(D9/B9,"") | F9: =IFERROR(C9/B9,"") | G9: =SUMIFS(Data!$G:$G,Data!$A:$A,">="&$A9,Data!$A:$A,"<="&($A9+6),Data!$B:$B,IF($B$2="All","*",$B$2)) | H9: =IFERROR(G9/D9,"") | I9: =G9-D9
A10: 46157 | B10: =SUMIFS(Data!$D:$D,Data!$A:$A,">="&$A10,Data!$A:$A,"<="&($A10+6),Data!$B:$B,IF($B$2="All","*",$B$2)) | C10: =SUMIFS(Data!$E:$E,Data!$A:$A,">="&$A10,Data!$A:$A,"<="&($A10+6),Data!$B:$B,IF($B$2="All","*",$B$2)) | D10: =SUMIFS(Data!$F:$F,Data!$A:$A,">="&$A10,Data!$A:$A,"<="&($A10+6),Data!$B:$B,IF($B$2="All","*",$B$2)) | E10: =IFERROR(D10/B10,"") | F10: =IFERROR(C10/B10,"") | G10: =SUMIFS(Data!$G:$G,Data!$A:$A,">="&$A10,Data!$A:$A,"<="&($A10+6),Data!$B:$B,IF($B$2="All","*",$B$2)) | H10: =IFERROR(G10/D10,"") | I10: =G10-D10
A11: 46150 | B11: =SUMIFS(Data!$D:$D,Data!$A:$A,">="&$A11,Data!$A:$A,"<="&($A11+6),Data!$B:$B,IF($B$2="All","*",$B$2)) | C11: =SUMIFS(Data!$E:$E,Data!$A:$A,">="&$A11,Data!$A:$A,"<="&($A11+6),Data!$B:$B,IF($B$2="All","*",$B$2)) | D11: =SUMIFS(Data!$F:$F,Data!$A:$A,">="&$A11,Data!$A:$A,"<="&($A11+6),Data!$B:$B,IF($B$2="All","*",$B$2)) | E11: =IFERROR(D11/B11,"") | F11: =IFERROR(C11/B11,"") | G11: =SUMIFS(Data!$G:$G,Data!$A:$A,">="&$A11,Data!$A:$A,"<="&($A11+6),Data!$B:$B,IF($B$2="All","*",$B$2)) | H11: =IFERROR(G11/D11,"") | I11: =G11-D11
A12: 46143 | B12: =SUMIFS(Data!$D:$D,Data!$A:$A,">="&$A12,Data!$A:$A,"<="&($A12+6),Data!$B:$B,IF($B$2="All","*",$B$2)) | C12: =SUMIFS(Data!$E:$E,Data!$A:$A,">="&$A12,Data!$A:$A,"<="&($A12+6),Data!$B:$B,IF($B$2="All","*",$B$2)) | D12: =SUMIFS(Data!$F:$F,Data!$A:$A,">="&$A12,Data!$A:$A,"<="&($A12+6),Data!$B:$B,IF($B$2="All","*",$B$2)) | E12: =IFERROR(D12/B12,"") | F12: =IFERROR(C12/B12,"") | G12: =SUMIFS(Data!$G:$G,Data!$A:$A,">="&$A12,Data!$A:$A,"<="&($A12+6),Data!$B:$B,IF($B$2="All","*",$B$2)) | H12: =IFERROR(G12/D12,"") | I12: =G12-D12
A13: 46136 | B13: =SUMIFS(Data!$D:$D,Data!$A:$A,">="&$A13,Data!$A:$A,"<="&($A13+6),Data!$B:$B,IF($B$2="All","*",$B$2)) | C13: =SUMIFS(Data!$E:$E,Data!$A:$A,">="&$A13,Data!$A:$A,"<="&($A13+6),Data!$B:$B,IF($B$2="All","*",$B$2)) | D13: =SUMIFS(Data!$F:$F,Data!$A:$A,">="&$A13,Data!$A:$A,"<="&($A13+6),Data!$B:$B,IF($B$2="All","*",$B$2)) | E13: =IFERROR(D13/B13,"") | F13: =IFERROR(C13/B13,"") | G13: =SUMIFS(Data!$G:$G,Data!$A:$A,">="&$A13,Data!$A:$A,"<="&($A13+6),Data!$B:$B,IF($B$2="All","*",$B$2)) | H13: =IFERROR(G13/D13,"") | I13: =G13-D13
A14: 46129 | B14: =SUMIFS(Data!$D:$D,Data!$A:$A,">="&$A14,Data!$A:$A,"<="&($A14+6),Data!$B:$B,IF($B$2="All","*",$B$2)) | C14: =SUMIFS(Data!$E:$E,Data!$A:$A,">="&$A14,Data!$A:$A,"<="&($A14+6),Data!$B:$B,IF($B$2="All","*",$B$2)) | D14: =SUMIFS(Data!$F:$F,Data!$A:$A,">="&$A14,Data!$A:$A,"<="&($A14+6),Data!$B:$B,IF($B$2="All","*",$B$2)) | E14: =IFERROR(D14/B14,"") | F14: =IFERROR(C14/B14,"") | G14: =SUMIFS(Data!$G:$G,Data!$A:$A,">="&$A14,Data!$A:$A,"<="&($A14+6),Data!$B:$B,IF($B$2="All","*",$B$2)) | H14: =IFERROR(G14/D14,"") | I14: =G14-D14
A15: 46122 | B15: =SUMIFS(Data!$D:$D,Data!$A:$A,">="&$A15,Data!$A:$A,"<="&($A15+6),Data!$B:$B,IF($B$2="All","*",$B$2)) | C15: =SUMIFS(Data!$E:$E,Data!$A:$A,">="&$A15,Data!$A:$A,"<="&($A15+6),Data!$B:$B,IF($B$2="All","*",$B$2)) | D15: =SUMIFS(Data!$F:$F,Data!$A:$A,">="&$A15,Data!$A:$A,"<="&($A15+6),Data!$B:$B,IF($B$2="All","*",$B$2)) | E15: =IFERROR(D15/B15,"") | F15: =IFERROR(C15/B15,"") | G15: =SUMIFS(Data!$G:$G,Data!$A:$A,">="&$A15,Data!$A:$A,"<="&($A15+6),Data!$B:$B,IF($B$2="All","*",$B$2)) | H15: =IFERROR(G15/D15,"") | I15: =G15-D15

Sheet Data
A1: =IFERROR(IMPORTDATA("https://ad-suite-production.up.railway.app/sheet-grid?key=uncvrd2026&v=15&sheet="&'Weekly Stats'!$B$3),"") | I1: DateKey | K1: Auto data from the server — don't type here.
I2: =ARRAYFORMULA(IF(LEN(A2:A100000)=0,"",TEXT(A2:A100000,"yyyy-mm-dd")))

Sheet Cohort
A1: =IFERROR(IMPORTDATA("https://ad-suite-production.up.railway.app/cohort-grid?key=uncvrd2026&v=15&sheet="&'Weekly Stats'!$B$3),"") | L1: Auto cohort data from the server (lifetime revenue per subscriber, by age) — don't type here.

Sheet Manual Spend
A1: MANUAL SPEND — type what you spent on OnlyFinder / OnlyGuider / OnlySeeker.
A2: Date | B2: Creator | C2: Platform | D2: Amount ($)
